Workbook
Name ACTION: #REF!
Name Z_6F1DCD5D_5DAC_4817_BF40_2B66F6F593E6_.wvu.PrintArea: Statistics!$B:$J
Name Z_2C0D9096_8D85_462A_A9B5_0B488ADB4269_.wvu.PrintArea: Statistics!$B:$J
Name Z_BE54E0AD_3725_4423_92D7_4F1C045BE1BC_.wvu.PrintArea: Statistics!$B:$J

Sheet Guideline
A1: Guideline to make and understand Unit Test Case
A3: 1. Overview
A4: - In the template, Unit test cases are based on functions. Each sheet presents test cases for one function.
A5: - Cover: General information of the project and Unit Test cases
A6: - FunctionList: The list of Classes and Functions in the document. + To control that the number of Unit TC meets customer's requirement or the norm, user should fill value for 'Normal number of Test cases/KLOC'.
A7: + Click on Function link to open the related Test cases of the function. Note: You should create new Function sheet before creating the link
A8: - Test Report: provive the overview results of Functions Unit test: Test coverage, Test successful coverage (Summary, for normal/abnormal/boundary cases)
A9: Note: Should check the formula of "Sub Total" if you add more functions
A11: 2. Content in Test function sheet
A12: 2.1 Combination of test cases.
A13: - To verify that number of Unit TC meets customer's requirement or not. User has to fill number LOC of tested function and fill value of 'Normal number test cases/KLOC' item in FunctionList sheet, which is required by customer or normal value. The number of lacked TC is shown in 'Lack of test cases' item.
A14: - If the number of Unit TC does not meet the requirement, creator should explain the reasons.
... A47: - Test requirement: Brief description about requirements which are tested in this function, it is not mandatory.

Sheet Cover
B2: UNIT TEST DOCUMENT
A4: Project Name | B4: Smart Japanese language learning app with AI. | E4: Creator | F4: ChuVV
A5: Project Code | B5: FKOTOAI | E5: Issue Date
A6: Document Code | B6: =B5&"_"&"TestReport"&"_"&"v1.0" -> FKOTOAI_TestReport_v1.0 | E6: Version | F6: 1
A9: Record of change
A10: Effective Date | B10: Version | C10: Change Item | D10: *A,D,M | E10: Change description | F10: Reference
A11: 46172 | B11: 1.0 | D11: A | E11: Create unit test document
A12: 46175 | B12: 1.0 | C12: Function list | D12: A | E12: Add unit tests of authentication functions | F12: FunctionList 1-5
A13: 46178 | B13: 1.0 | C13: Function list | D13: A | E13: Add unit tests of account functions | F13: FunctionList 6, 7
B14: 1.0 | C14: Function list | D14: A
B15: 1.0 | C15: Function list | D15: M
B16: 1.0 | C16: Function list | D16: A
B17: 1.0 | C17: Function list | D17: M
B18: 1.0 | C18: Function list | D18: A
B19: 1.0 | C19: Function list | D19: A
B20: 1.0 | C20: Function list | D20: A
B21: 1.0 | C21: Function list | D21: A
B22: 1.0 | C22: Function list | D22: M
B23: 1.0 | C23: Function list | D23: M
B24: 1.0 | C24: Function list | D24: M
B25: 1.0 | C25: Function list | D25: M

Sheet Functions
E2: Function List
A4: Project Name | E4: =Cover!B4 -> Smart Japanese language learning app with AI.
A5: Project Code | E5: =Cover!B5 -> FKOTOAI
A6: Normal number of Test cases/KLOC | E6: 100
A7: Test Environment Setup Description | E7: <List enviroment requires in this system 1. Server 2. Database 3. Web Browser ... >
A10: No | B10: Module Name | C10: Method Name | D10: Sheet Name | E10: Description | F10: Pre-Condition
A11: 1 | B11: AuthService | C11: login | D11: register | E11: Authenticates and logs the student into the system. | F11: Valid credentials are provided.
A12: 2 | C12: resetPassword | E12: Registers a new student account and sets the initial level. | F12: Required information fields are provided and valid.
C13: logout
C14: verifyOTP
A15: 3 | C15: forgotPassword | E15: Sends a password reset email to the user. | F15: A valid, registered email address is provided.
A16: 4 | B16: UserService | C16: updateProfile | E16: Updates student's personal info, avatar, password, and target level. | F16: The student is authenticated and logged in.
A17: 5 | C17: manageStudentAccounts | E17: Admin monitors accounts and locks/unlocks users suspected of abuse. | F17: The Admin is authenticated; the target student account exists.
A18: 6 | B18: ContentService | C18: manageVocabChapters | E18: Student creates, edits, views, or deletes their vocabulary sets. | F18: The student is authenticated
A19: 7 | C19: studyFlashcards | E19: Student interacts with flashcards to study vocabulary. | F19: The target vocabulary chapter/set exists.
A20: 8 | C20: getLearningProgress | E20: Retrieves and displays the student's learning progress and performance. | F20: The student is authenticated and has learning history.
A21: 9 | C21: manageVocabBank | E21: Admin performs CRUD or bulk imports vocabulary/Kanji via Excel. | F21: The Admin is authenticated; the Excel file is valid.
A22: 10 | C22: manageArticles | E22: Admin creates, edits, deletes, and categorizes N5/N4 reading articles. | F22: The Admin is authenticated.
A23: 11 | B23: ReadingService | C23: readArticles | E23: Student reads standardized articles with quick pop-up dictionary support. | F23: The student is authenticated; articles exist in the system.
A24: 12 | B24: SmartLookupService | C24: lookupByImage | E24: Extracts meanings of Japanese text using mobile camera (OCR). | F24: A valid image is captured or uploaded
A25: 13 | C25: lookupByHandwriting | E25: Finds meanings and stroke orders from Kanji drawn on a digital canvas. | F25: Handwriting stroke coordinates are provided.
A26: 14 | C26: analyzeContext | E26: Requests LLM (AI) to analyze complex grammar and context of text. | F26: A specific text segment is highlighted/selected by the user.
A27: 15 | B27: ExamService | C27: takeQuizOrExam | E27: Student takes topic quizzes or time-strict mock exams for auto-grading. | F27: The student has an active premium subscription (if required).
A28: 16 | C28: triggerAIChallenge | E28: Generates a personalized adaptive test based on weak vocabulary. | F28: The student has recorded weak vocabulary data.
A29: 17 | C29: manageQuestionBank | E29: Admin manages multiple-choice questions, media, and bulk imports. | F29: The Admin is authenticated; valid question data/file is provided.
A30: 18 | C30: configureExamTemplate | E30: Admin sets up parameters (time, passing score, shuffle) for mock exams. | F30: The Admin is authenticated.
A31: 19 | B31: MatchmakingService | C31: playRankMatch | E31: Student competes against peers in real-time vocabulary quizzes. | F31: The student is authenticated and in the matchmaking lobby.
A32: 20 | C32: viewLeaderboard | E32: Displays national or weekly ranking boards based on Elo points. | F32: The student is authenticated.
A33: 21 | B33: PaymentService | C33: purchaseSubscription | E33: Student purchases premium packages via VNPay QR code. | F33: A valid subscription package is selected.
A34: 22 | C34: manageSubscriptions | E34: Admin configures pricing, duration, and status of premium packages. | F34: The Admin is authenticated.
A35: 23 | B35: DashboardService | C35: viewSystemDashboard | E35: Admin views real-time statistics on revenue, contests, and analytics. | F35: The Admin is authenticated.
A36: 24

Sheet Statistics
B2: UNIT TEST REPORT
B4: Project Name | C4: =Cover!B4 -> Smart Japanese language learning app with AI. | E4: Creator | G4: ChuVV
B5: Project Code | C5: =Cover!B5 -> FKOTOAI | E5: Reviewer/Approver | G5: VietDX
B6: Document Code | C6: =C5&"_"&"Unit Test Report"&"_"&"v1.0" -> FKOTOAI_Unit Test Report_v1.0 | E6: Issue Date
B7: Notes
B9: No | C9: Function code | D9: Passed | E9: Failed | F9: Untested | G9: N | H9: A | I9: B | J9: Total Test Cases
B10: 1 | C10: login | D10: =logout!A5 -> 18 | E10: =logout!C5 -> 0 | F10: =logout!E5 -> 0 | G10: =logout!J5 -> 2 | H10: =logout!K5 -> 13 | I10: =logout!L5 -> 3 | J10: =logout!M5 -> 18
B11: 2 | C11: register | D11: =login!A5 -> 7 | E11: =login!C5 -> 0 | F11: =login!E5 -> 9 | G11: =login!J5 -> 3 | H11: =login!K5 -> 3 | I11: =login!L5 -> 1 | J11: =login!M5 -> 16
B12: 3 | C12: forgotPassword | D12: =requestOTP!A5 -> 5 | E12: =requestOTP!C5 -> 0 | F12: =requestOTP!E5 -> 3 | G12: =requestOTP!J5 -> 2 | H12: =requestOTP!K5 -> 3 | I12: =requestOTP!L5 -> 0 | J12: =requestOTP!M5 -> 8
B13: 4 | C13: updateProfile | D13: =studentHome!A5 -> 9 | E13: =studentHome!C5 -> 0 | F13: =studentHome!E5 -> 0 | G13: =studentHome!J5 -> 1 | H13: =studentHome!K5 -> 7 | I13: =studentHome!L5 -> 1 | J13: =studentHome!M5 -> 9
B14: 5 | C14: manageStudentAccounts | D14: =submitFlashcard!A5 -> 13 | E14: =submitFlashcard!C5 -> 0 | F14: =submitFlashcard!E5 -> 0 | G14: =submitFlashcard!J5 -> 1 | H14: =submitFlashcard!K5 -> 10 | I14: =submitFlashcard!L5 -> 2 | J14: =submitFlashcard!M5 -> 13
B15: 6 | C15: manageVocabChapters | D15: =viewFlashcard!A5 -> 21 | E15: =viewFlashcard!C5 -> 0 | F15: =viewFlashcard!E5 -> 0 | G15: =viewFlashcard!J5 -> 2 | H15: =viewFlashcard!K5 -> 16 | I15: =viewFlashcard!L5 -> 3 | J15: =viewFlashcard!M5 -> 21
B16: 7 | C16: studyFlashcards | D16: =submitFlashcard!A5 -> #REF! | E16: =submitFlashcard!C5 -> #REF! | F16: =submitFlashcard!E5 -> #REF! | G16: =submitFlashcard!J5 -> #REF! | H16: =submitFlashcard!K5 -> #REF! | I16: =submitFlashcard!L5 -> #REF! | J16: =submitFlashcard!M5 -> #REF!
B17: 8 | C17: getLearningProgress | D17: =IFERROR(__xludf.DUMMYFUNCTION("SPLIT(TEXTJOIN("","", TRUE, viewLearningProgress!A5, viewLearningProgress!C5, viewLearningProgress!E5, viewLearningProgress!J5, viewLearningProgress!K5, viewLearningProgress!L5, viewLearningProgress!M5), "","") "),14.0) -> 14 | E17: =IFERROR(__xludf.DUMMYFUNCTION("""COMPUTED_VALUE"""),0.0) -> 0 | F17: =IFERROR(__xludf.DUMMYFUNCTION("""COMPUTED_VALUE"""),0.0) -> 0 | G17: =IFERROR(__xludf.DUMMYFUNCTION("""COMPUTED_VALUE"""),2.0) -> 2 | H17: =IFERROR(__xludf.DUMMYFUNCTION("""COMPUTED_VALUE"""),10.0) -> 10 | I17: =IFERROR(__xludf.DUMMYFUNCTION("""COMPUTED_VALUE"""),2.0) -> 2 | J17: =IFERROR(__xludf.DUMMYFUNCTION("""COMPUTED_VALUE"""),14.0) -> 14
B18: 9 | C18: manageVocabBank | D18: =IFERROR(__xludf.DUMMYFUNCTION("SPLIT(TEXTJOIN("","", TRUE, changeStatusProject!A5, changeStatusProject!C5, changeStatusProject!E5, changeStatusProject!J5, changeStatusProject!K5, changeStatusProject!L5, changeStatusProject!M5), "","") "),"#REF!") -> #REF!
B19: 10 | C19: manageArticles | D19: =IFERROR(__xludf.DUMMYFUNCTION("SPLIT(TEXTJOIN("","", TRUE, getDetailChapter!A5, getDetailChapter!C5, getDetailChapter!E5, getDetailChapter!J5, getDetailChapter!K5, getDetailChapter!L5, getDetailChapter!M5), "","") "),"#REF!") -> #REF!
B20: 11 | C20: readArticles | D20: =IFERROR(__xludf.DUMMYFUNCTION("SPLIT(TEXTJOIN("","", TRUE, updateChapterDetail!A5, updateChapterDetail!C5, updateChapterDetail!E5, updateChapterDetail!J5, updateChapterDetail!K5, updateChapterDetail!L5, updateChapterDetail!M5), "","") "),5.0) -> 5 | E20: =IFERROR(__xludf.DUMMYFUNCTION("""COMPUTED_VALUE"""),0.0) -> 0 | F20: =IFERROR(__xludf.DUMMYFUNCTION("""COMPUTED_VALUE"""),0.0) -> 0 | G20: =IFERROR(__xludf.DUMMYFUNCTION("""COMPUTED_VALUE"""),1.0) -> 1 | H20: =IFERROR(__xludf.DUMMYFUNCTION("""COMPUTED_VALUE"""),4.0) -> 4 | I20: =IFERROR(__xludf.DUMMYFUNCTION("""COMPUTED_VALUE"""),0.0) -> 0 | J20: =IFERROR(__xludf.DUMMYFUNCTION("""COMPUTED_VALUE"""),5.0) -> 5
B21: 12 | C21: lookupByImage | D21: =IFERROR(__xludf.DUMMYFUNCTION("SPLIT(TEXTJOIN("","", TRUE, addCategory!A5, addCategory!C5, addCategory!E5, addCategory!J5, addCategory!K5, addCategory!L5, addCategory!M5), "","") "),"#REF!") -> #REF!
B22: 13 | C22: lookupByHandwriting | D22: =IFERROR(__xludf.DUMMYFUNCTION("SPLIT(TEXTJOIN("","", TRUE, getCategorybyID!A5, getCategorybyID!C5, getCategorybyID!E5, getCategorybyID!J5, getCategorybyID!K5, getCategorybyID!L5, getCategorybyID!M5), "","") "),"#REF!") -> #REF!
B23: 14 | C23: analyzeContext | D23: =IFERROR(__xludf.DUMMYFUNCTION("SPLIT(TEXTJOIN("","", TRUE, updateCategory!A5, updateCategory!C5, updateCategory!E5, updateCategory!J5, updateCategory!K5, updateCategory!L5, updateCategory!M5), "","") "),"#REF!") -> #REF!
B24: 15 | C24: takeQuizOrExam | D24: =IFERROR(__xludf.DUMMYFUNCTION("SPLIT(TEXTJOIN("","", TRUE, deleteCategory!A5, deleteCategory!C5, deleteCategory!E5, deleteCategory!J5, deleteCategory!K5, deleteCategory!L5, deleteCategory!M5), "","") "),"#REF!") -> #REF!
B25: 16 | C25: triggerAIChallenge | D25: =IFERROR(__xludf.DUMMYFUNCTION("SPLIT(TEXTJOIN("","", TRUE, changeStatusCategory!A5, changeStatusCategory!C5, changeStatusCategory!E5, changeStatusCategory!J5, changeStatusCategory!K5, changeStatusCategory!L5, changeStatusCategory!M5), "","") "),"#REF!") -> #REF!
B26: 17 | C26: manageQuestionBank | D26: =IFERROR(__xludf.DUMMYFUNCTION("SPLIT(TEXTJOIN("","", TRUE, addModule!A5, addModule!C5, addModule!E5, addModule!J5, addModule!K5, addModule!L5, addModule!M5), "","") "),"#REF!") -> #REF!
B27: 18 | C27: configureExamTemplate | D27: =IFERROR(__xludf.DUMMYFUNCTION("SPLIT(TEXTJOIN("","", TRUE, getModulebyProject!A5, getModulebyProject!C5, getModulebyProject!E5, getModulebyProject!J5, getModulebyProject!K5, getModulebyProject!L5, getModulebyProject!M5), "","") "),"#REF!") -> #REF!
B28: 19 | C28: playRankMatch | D28: =IFERROR(__xludf.DUMMYFUNCTION("SPLIT(TEXTJOIN("","", TRUE, updateModule!A5, updateModule!C5, updateModule!E5, updateModule!J5, updateModule!K5, updateModule!L5, updateModule!M5), "","") "),"#REF!") -> #REF!
B29: 20 | C29: viewLeaderboard | D29: =IFERROR(__xludf.DUMMYFUNCTION("SPLIT(TEXTJOIN("","", TRUE, deleteModule!A5, deleteModule!C5, deleteModule!E5, deleteModule!J5, deleteModule!K5, deleteModule!L5, deleteModule!M5), "","") "),"#REF!") -> #REF!
B30: 21 | C30: purchaseSubscription | D30: =IFERROR(__xludf.DUMMYFUNCTION("SPLIT(TEXTJOIN("","", TRUE, createContentItem!A5, createContentItem!C5, createContentItem!E5, createContentItem!J5, createContentItem!K5, createContentItem!L5, createContentItem!M5), "","") "),"#REF!") -> #REF!
B31: 22 | C31: manageSubscriptions | D31: =IFERROR(__xludf.DUMMYFUNCTION("SPLIT(TEXTJOIN("","", TRUE, getFullContentItem!A5, getFullContentItem!C5, getFullContentItem!E5, getFullContentItem!J5, getFullContentItem!K5, getFullContentItem!L5, getFullContentItem!M5), "","") "),"#REF!") -> #REF!
B32: 23 | C32: viewSystemDashboard | D32: =IFERROR(__xludf.DUMMYFUNCTION("SPLIT(TEXTJOIN("","", TRUE, getContentItembyID!A5, getContentItembyID!C5, getContentItembyID!E5, getContentItembyID!J5, getContentItembyID!K5, getContentItembyID!L5, getContentItembyID!M5), "","") "),"#REF!") -> #REF!
B33: 24 | C33: login | D33: =IFERROR(__xludf.DUMMYFUNCTION("SPLIT(TEXTJOIN("","", TRUE, deleteContentItem!A5, deleteContentItem!C5, deleteContentItem!E5, deleteContentItem!J5, deleteContentItem!K5, deleteContentItem!L5, deleteContentItem!M5), "","") "),"#REF!") -> #REF!
B34: 25 | C34: register | D34: =IFERROR(__xludf.DUMMYFUNCTION("SPLIT(TEXTJOIN("","", TRUE, addQuiz!A5, addQuiz!C5, addQuiz!E5, addQuiz!J5, addQuiz!K5, addQuiz!L5, addQuiz!M5), "","") "),"#REF!") -> #REF!
B35: 26 | C35: forgotPassword | D35: =IFERROR(__xludf.DUMMYFUNCTION("SPLIT(TEXTJOIN("","", TRUE, updateQuiz!A5, updateQuiz!C5, updateQuiz!E5, updateQuiz!J5, updateQuiz!K5, updateQuiz!L5, updateQuiz!M5), "","") "),"#REF!") -> #REF!
B36: 27 | C36: updateProfile | D36: =IFERROR(__xludf.DUMMYFUNCTION("SPLIT(TEXTJOIN("","", TRUE, deleteQuiz!A5, deleteQuiz!C5, deleteQuiz!E5, deleteQuiz!J5, deleteQuiz!K5, deleteQuiz!L5, deleteQuiz!M5), "","") "),"#REF!") -> #REF!
B37: 28 | C37: manageStudentAccounts | D37: =IFERROR(__xludf.DUMMYFUNCTION("SPLIT(TEXTJOIN("","", TRUE, createAssignment!A5, createAssignment!C5, createAssignment!E5, createAssignment!J5, createAssignment!K5, createAssignment!L5, createAssignment!M5), "","") "),"#REF!") -> #REF!
B38: 29 | C38: manageVocabChapters | D38: =IFERROR(__xludf.DUMMYFUNCTION("SPLIT(TEXTJOIN("","", TRUE, updateAssignment!A5, updateAssignment!C5, updateAssignment!E5, updateAssignment!J5, updateAssignment!K5, updateAssignment!L5, updateAssignment!M5), "","") "),"#REF!") -> #REF!
B39: 30 | C39: studyFlashcards | D39: =IFERROR(__xludf.DUMMYFUNCTION("SPLIT(TEXTJOIN("","", TRUE, deleteAssignment!A5, deleteAssignment!C5, deleteAssignment!E5, deleteAssignment!J5, deleteAssignment!K5, deleteAssignment!L5, deleteAssignment!M5), "","") "),"#REF!") -> #REF!
B40: 31 | C40: getLearningProgress | D40: =IFERROR(__xludf.DUMMYFUNCTION("SPLIT(TEXTJOIN("","", TRUE, getAssignmentbyProject!A5, getAssignmentbyProject!C5, getAssignmentbyProject!E5, getAssignmentbyProject!J5, getAssignmentbyProject!K5, getAssignmentbyProject!L5, getAssignmentbyProject!M5), "","") "),"#REF!") -> #REF!
B41: 32 | C41: manageVocabBank | D41: =IFERROR(__xludf.DUMMYFUNCTION("SPLIT(TEXTJOIN("","", TRUE, importQuestion!A5, importQuestion!C5, importQuestion!E5, importQuestion!J5, importQuestion!K5, importQuestion!L5, importQuestion!M5), "","") "),"#REF!") -> #REF!
B42: 33 | C42: manageArticles | D42: =IFERROR(__xludf.DUMMYFUNCTION("SPLIT(TEXTJOIN("","", TRUE, getQuestionsByQuiz!A5, getQuestionsByQuiz!C5, getQuestionsByQuiz!E5, getQuestionsByQuiz!J5, getQuestionsByQuiz!K5, getQuestionsByQuiz!L5, getQuestionsByQuiz!M5), "","") "),"#REF!") -> #REF!
B43: 34 | C43: readArticles | D43: =IFERROR(__xludf.DUMMYFUNCTION("SPLIT(TEXTJOIN("","", TRUE, getChapterList!A5, getChapterList!C5, getChapterList!E5, getChapterList!J5, getChapterList!K5, getChapterList!L5, getChapterList!M5), "","") "),4.0) -> 4 | E43: =IFERROR(__xludf.DUMMYFUNCTION("""COMPUTED_VALUE"""),0.0) -> 0 | F43: =IFERROR(__xludf.DUMMYFUNCTION("""COMPUTED_VALUE"""),0.0) -> 0 | G43: =IFERROR(__xludf.DUMMYFUNCTION("""COMPUTED_VALUE"""),1.0) -> 1 | H43: =IFERROR(__xludf.DUMMYFUNCTION("""COMPUTED_VALUE"""),3.0) -> 3 | I43: =IFERROR(__xludf.DUMMYFUNCTION("""COMPUTED_VALUE"""),0.0) -> 0 | J43: =IFERROR(__xludf.DUMMYFUNCTION("""COMPUTED_VALUE"""),4.0) -> 4
...

Sheet login
A1: Code Module | C1: UserController | E1: Method | N1: Login
A2: Created By | C2: ChuVV | E2: Executed By | N2: ChuVV
A3: Test requirement
A4: Passed | C4: Failed | E4: Untested | J4: N/A/B | M4: Total Test Cases
A5: =COUNTIF(E37:ID37,"P") -> 7 | C5: =COUNTIF(E37:ID37,"F") -> 0 | E5: =SUM(M5,-A5,-C5) -> 9 | J5: =COUNTIF(A36:HZ36,"N") -> 3 | K5: =COUNTIF(A36:HZ36,"A") -> 3 | L5: =COUNTIF(A36:HZ36,"B") -> 1 | M5: =COUNTA(A7:HR7) -> 16
E7: UTCID01 | F7: UTCID02 | G7: UTCID03 | H7: UTCID04 | I7: UTCID05 | J7: UTCID06 | K7: UTCID07 | L7: UTCID08 | M7: UTCID09 | N7: UTCID10 | O7: UTCID11 | P7: UTCID12 | Q7: UTCID13 | R7: UTCID14 | S7: UTCID15 | T7: UTCID16
A8: Condition | B8: Precondition
D9: Connected to the server | E9: O | F9: O | G9: O | H9: O | I9: O | J9: O | K9: O
B10: email
C11: registed email | D11: nanhphuong2005@gmail.com | E11: O | I11: O | J11: O | K11: O | M11: O
C12: emty email | F12: O
C13: unregisted email | D13: nonexistent@gmail.com | G13: O
C14: invalid email format | D14: student123 | H14: O
C15: space | L15: O
B16: password
C17: correct password | D17: anhphuong | E17: O | F17: O | G17: O | H17: O | L17: O
C18: emty password | I18: O
C19: short password | D19: 123 | J19: O
C20: incorrect password | D20: 123456 | K20: O
C21: space | M21: O
A22: Confirm | B22: Return
D23: TRUE | E23: O
D24: FALSE | F24: O | G24: O | H24: O | I24: O | J24: O | K24: O | L24: O | M24: O
B25: Exception
B28: Log message
D29: "Login successful" | E29: O
D30: "The Email is required." | F30: O | L30: O
D31: " Password is required." | I31: O | M31: O
D32: "Email is invalid." | H32: O
D33: "Student not found" | G33: O
D34: "Unauthenticated" | K34: O
D35: "The Password is invalid." | J35: O
A36: Result | B36: Type(N : Normal, A : Abnormal, B : Boundary) | E36: N | F36: N | G36: A | H36: A | I36: A | J36: B | K36: N
B37: Passed/Failed | E37: P | F37: P | G37: P | H37: P | I37: P | J37: P | K37: P
B38: Executed Date | E38: 45931 | F38: 45931 | G38: 45931 | H38: 45931 | I38: 45931 | J38: 45931 | K38: 45931
B39: Defect ID

Sheet requestOTP
A1: Code Module | C1: UserController | E1: Method | N1: Login
A2: Created By | C2: ChuVV | E2: Executed By | N2: ChuVV
A3: Test requirement
A4: Passed | C4: Failed | E4: Untested | J4: N/A/B | M4: Total Test Cases
A5: =COUNTIF(E27:IA27,"P") -> 5 | C5: =COUNTIF(E27:IA27,"F") -> 0 | E5: =SUM(M5,-A5,-C5) -> 3 | J5: =COUNTIF(A26:HW26,"N") -> 2 | K5: =COUNTIF(B26:HX26,"A") -> 3 | L5: =COUNTIF(C26:HY26,"B") -> 0 | M5: =COUNTA(A7:HO7) -> 8
E7: UTCID01 | F7: UTCID02 | G7: UTCID03 | H7: UTCID04 | I7: UTCID05 | J7: UTCID06 | K7: UTCID07 | L7: UTCID08
A8: Condition | B8: Precondition
D9: Connected to the server | E9: O | F9: O | G9: O | H9: O | I9: O
B10: email
C11: registed email | D11: nanhphuong2005@gmail.com | E11: O
C12: unregisted email | D12: nonexist@gmail.com | F12: O
C13: emty email | G13: O
C14: invalid email format | D14: student123 | H14: O
C15: space | I15: O
A16: Confirm | B16: Return
D17: TRUE | E17: O
D18: FALSE | F18: O | G18: O | H18: O | I18: O
B19: Exception
B22: Log message
D23: "OTP sent successfully" | E23: O | F23: O
D24: "Invalid email address" | H24: O
D25: "Email cannot be empty" | G25: O | I25: O
A26: Result | B26: Type(N : Normal, A : Abnormal, B : Boundary) | E26: N | F26: N | G26: A | H26: A | I26: A
B27: Passed/Failed | E27: P | F27: P | G27: P | H27: P | I27: P
B28: Executed Date | E28: 45932 | F28: 45932 | G28: 45932 | H28: 45932 | I28: 45932
B29: Defect ID

Sheet Verify OTP
A1: Code Module | C1: UserController | E1: Method | N1: Login
A2: Created By | C2: ChuVV | E2: Executed By | N2: ChuVV
A3: Test requirement
A4: Passed | C4: Failed | E4: Untested | J4: N/A/B | M4: Total Test Cases
A5: =COUNTIF(E38:IA38,"P") -> 8 | C5: =COUNTIF(E38:IA38,"F") -> 0 | E5: =SUM(M5,-A5,-C5) -> 0 | J5: =COUNTIF(A37:HW37,"N") -> 2 | K5: =COUNTIF(B37:HX37,"A") -> 5 | L5: =COUNTIF(C37:HY37,"B") -> 1 | M5: =COUNTA(A7:HO7) -> 8
E7: UTCID01 | F7: UTCID02 | G7: UTCID03 | H7: UTCID04 | I7: UTCID05 | J7: UTCID06 | K7: UTCID07 | L7: UTCID08
A8: Condition | B8: Precondition
D9: Connected to the server | E9: O | F9: O | G9: O | H9: O | I9: O | J9: O | K9: O | L9: O
B10: OTP | C10: correct OTP | D10: null | E10: O | L10: O
C11: incorrect OTP
C12: expired OTP | E12: O
C13: non-numeric OTP
C14: wrong length OTP
C15: emty OTP
B16: email
C17: registed email | D17: student14@gmail.com | E17: O
C18: unregisted email | D18: student13@fpt.edu.vn | F18: O
C19: emty email | D19: student16@gmail.com | G19: O
C20: invalid email format | D20: student123 | H20: O
C21: with space | D21: admin@gmail.com | I21: O
C22: 255 characters | D22: aaa.....a | J22: O
C23: does not exists in the database | D23: student15@fpt.edu.vn | K23: O
A24: Confirm | B24: Return
D25: TRUE | E25: O | F25: O
D26: FALSE | G26: O | H26: O | I26: O | J26: O | K26: O | L26: O
B27: Exception
B30: Log message
D31: "OTP verified successfully" | E31: O | F31: O
D32: "Invalid OTP" | H32: O
D33: "OTP must be 6 numeric characters"
D34: "OTP cannot be empty" | G34: O
D35: "Invalid email address" | I35: O | L35: O
D36: "Email cannot be empty" | K36: O
A37: Result | B37: Type(N : Normal, A : Abnormal, B : Boundary) | E37: N | F37: N | G37: A | H37: A | I37: A | J37: B | K37: A | L37: A
B38: Passed/Failed | E38: P | F38: P | G38: P | H38: P | I38: P | J38: P | K38: P | L38: P
B39: Executed Date | E39: 45932 | F39: 45932 | G39: 45932 | H39: 45932 | I39: 45932 | J39: 45932 | K39: 45932 | L39: 45932
B40: Defect ID

Sheet logout
A1: Code Module | C1: UserController | E1: Method | K1: Register
A2: Created By | C2: ChuVV | E2: Executed By | K2: ChuVV
A3: Test requirement
A4: Passed | C4: Failed | E4: Untested | J4: N/A/B | M4: Total Test Cases
A5: =COUNTIF(E26:IA26,"P") -> 18 | C5: =COUNTIF(E26:IA26,"F") -> 0 | E5: =SUM(M5,-A5,-C5) -> 0 | J5: =COUNTIF(A25:HW25,"N") -> 2 | K5: =COUNTIF(B25:HX25,"A") -> 13 | L5: =COUNTIF(C25:HY25,"B") -> 3 | M5: =COUNTA(A7:HO7) -> 18
E7: UTCID01 | F7: UTCID02 | G7: UTCID03 | H7: UTCID04 | I7: UTCID05 | J7: UTCID06 | K7: UTCID07 | L7: UTCID08 | M7: UTCID09 | N7: UTCID10 | O7: UTCID11 | P7: UTCID12 | Q7: UTCID13 | R7: UTCID14 | S7: UTCID15 | T7: UTCID16 | U7: UTCID17 | V7: UTCID18
A8: Condition | B8: Precondition
D9: Connected to the server | E9: O | F9: O | G9: O | H9: O
B10: token
C11: valid token | D11: eyJhbGciOiJIUzUxMiJ9.eyJzdHVkZW50SUQiOjEsImlzcyI6ImNodXZ2ZGVwemFpIiwic3ViIjoibWluaGFuaEBleGFtcGxlLmNvbSIsImV4cCI6MTc4MTM2OTg2NCwiaWF0IjoxNzgxMTk3MDY0LCJqdGkiOiI5ZjJhNTUyZS01OWVhLTRiZTctYmZjMi1mZDUxOTc1NmNjMjgifQ.yWMS9Q3X3GOsYni4o5hbN2Q0vHGEwUn7tcqp0MbNGembXQvM1mjzihbWOL405Tj3oE2XXM8OrI9X0PhJtd4H7A | E11: O
C12: expire token | D12: eyJhbGciOiJIUzUxMiJ9.eyJzdHVkZW50SUQiOjEsImlzcyI6ImNodXZ2ZGVwemFpIiwic3ViIjoibWluaGFuaEBleGFtcGxlLmNvbSIsImV4cCI6MTc4MTM2OTg2NCwiaWF0IjoxNzgxMTk3MDY0LCJqdGkiOiI5ZjJhNTUyZS01OWVhLTRiZTctYmZjMi1mZDUxOTc1NmNjMjgifQ.yWMS9Q3X3GOsYni4o5hbN2Q0vHGEwUn7tcqp0MbNGembXQvM1mjzihbWOL405Tj3oE2XXM8OrI9X0PhJtd4H7A | F12: O
C13: empty token | G13: O
C14: invalid format token | D14: invalid-token-123 | H14: O
D15: null
A16: Confirm | B16: Return
D17: TRUE | E17: O
D18: FALSE | F18: O | G18: O | H18: O
B19: Exception
B22: Log message
D23: "Logout Successfuly" | E23: O | F23: O
D24: "IUnauthenticated" | G24: O | H24: O
A25: Result | B25: Type(N : Normal, A : Abnormal, B : Boundary) | E25: N | F25: B | G25: A | H25: A | I25: A | J25: B | K25: N | L25: A | M25: A | N25: A | O25: A | P25: A | Q25: A | R25: A | S25: A | T25: A | U25: B | V25: A
B26: Passed/Failed | E26: P | F26: P | G26: P | H26: P | I26: P | J26: P | K26: P | L26: P | M26: P | N26: P | O26: P | P26: P | Q26: P | R26: P | S26: P | T26: P | U26: P | V26: P
B27: Executed Date | E27: 45931 | F27: 45931 | G27: 45931 | H27: 45931 | I27: 45931 | J27: 45931 | K27: 45931 | L27: 45931 | M27: 45931 | N27: 45931 | O27: 45931 | P27: 45931 | Q27: 45931 | R27: 45931 | S27: 45931 | T27: 45931 | U27: 45931 | V27: 45931
B28: Defect ID

Sheet studentHome
A1: Code Module | C1: UserController | E1: Method | N1: Login
A2: Created By | C2: ChuVV | E2: Executed By | N2: ChuVV
A3: Test requirement
A4: Passed | C4: Failed | E4: Untested | J4: N/A/B | M4: Total Test Cases
A5: =COUNTIF(E28:HZ28,"P") -> 9 | C5: =COUNTIF(E28:HZ28,"F") -> 0 | E5: =SUM(M5,-A5,-C5) -> 0 | J5: =COUNTIF(A27:HV27,"N") -> 1 | K5: =COUNTIF(B27:HW27,"A") -> 7 | L5: =COUNTIF(C27:HX27,"B") -> 1 | M5: =COUNTA(A7:HN7) -> 9
E7: UTCID01 | F7: UTCID02 | G7: UTCID03 | H7: UTCID04 | I7: UTCID05 | J7: UTCID06 | K7: UTCID07 | L7: UTCID08 | M7: UTCID09
A8: Condition | B8: Precondition
D9: Connected to the server | E9: O | F9: O | G9: O | H9: O
B10: studentId
C11: valid student ID | D11: 1 | E11: O
C12: Non-existent student ID | D12: 9999 | F12: O
C13: Non-numeric student ID | D13: abc | G13: O
C14: space | H14: O
A16: Confirm | B16: Return
D17: TRUE | E17: O
D18: FALSE | F18: O | G18: O | H18: O
B19: Exception
B22: Log message
D23: "success" | E23: O
D24: "Student not found" | F24: O
D25: "Old password is required" | F25: O
D26: "This exception is undedefined" | G26: O | H26: O
A27: Result | B27: Type(N : Normal, A : Abnormal, B : Boundary) | E27: N | F27: A | G27: A | H27: A | I27: A | J27: A | K27: B | L27: A | M27: A
B28: Passed/Failed | E28: P | F28: P | G28: P | H28: P | I28: P | J28: P | K28: P | L28: P | M28: P
B29: Executed Date | E29: 45932 | F29: 45932 | G29: 45932 | H29: 45932 | I29: 45932 | J29: 45932 | K29: 45932 | L29: 45932 | M29: 45932
B30: Defect ID

Sheet viewFlashcard
A1: Code Module | C1: UserController | E1: Method | N1: Login
A2: Created By | C2: ChuVV | E2: Executed By | N2: ChuVV
A3: Test requirement
A4: Passed | C4: Failed | E4: Untested | J4: N/A/B | M4: Total Test Cases
A5: =COUNTIF(E30:IE30,"P") -> 21 | C5: =COUNTIF(E30:IE30,"F") -> 0 | E5: =SUM(M5,-A5,-C5) -> 0 | J5: =COUNTIF(A29:IA29,"N") -> 2 | K5: =COUNTIF(B29:IB29,"A") -> 16 | L5: =COUNTIF(C29:IC29,"B") -> 3 | M5: =COUNTA(A7:HS7) -> 21
E7: UTCID01 | F7: UTCID02 | G7: UTCID03 | H7: UTCID04 | I7: UTCID05 | J7: UTCID06 | K7: UTCID07 | L7: UTCID08 | M7: UTCID09 | N7: UTCID10 | O7: UTCID11 | P7: UTCID12 | Q7: UTCID13 | R7: UTCID14 | S7: UTCID15 | T7: UTCID16 | U7: UTCID17 | V7: UTCID18 | W7: UTCID19 | X7: UTCID20 | Y7: UTCID21
A8: Condition | B8: Precondition
D9: Connected to the server | E9: O | F9: O | G9: O | H9: O | I9: O
B10: chapterID
C11: Valid chapter ID | D11: 1 | E11: O | H11: O | I11: O | J11: O
C12: Non-existent chapter ID | D12: 9999 | F12: O
C13: Non-numeric chapter ID | D13: abc | G13: O
C14: Empty chapter id | K14: O
B15: studentID
C16: Valid student ID | D16: 1 | E16: O | F16: O | G16: O | K16: O
C17: empty student ID | D17: student13@fpt.edu.vn | H17: O | I17: O
C18: Non-numeric student ID | D18: student16@gmail.com | J18: O
A19: Confirm | B19: Return
D20: TRUE | E20: O
D21: FALSE | F21: O | G21: O | H21: O | I21: O
B22: Exception
B25: Log message
D26: "Flashcards retrieved successfully" | E26: O
D27: "This exception is undedefined" | G27: O | H27: O | I27: O | J27: O | K27: O
D28: "This exception is undedefined" (blank array) | F28: O
A29: Result | B29: Type(N : Normal, A : Abnormal, B : Boundary) | E29: N | F29: A | G29: A | H29: A | I29: A | J29: A | K29: B | L29: N | M29: A | N29: A | O29: A | P29: B | Q29: A | R29: A | S29: A | T29: A | U29: A | V29: B | W29: A | X29: A | Y29: A
B30: Passed/Failed | E30: P | F30: P | G30: P | H30: P | I30: P | J30: P | K30: P | L30: P | M30: P | N30: P | O30: P | P30: P | Q30: P | R30: P | S30: P | T30: P | U30: P | V30: P | W30: P | X30: P | Y30: P
B31: Executed Date | E31: 45933 | F31: 45933 | G31: 45933 | H31: 45933 | I31: 45933 | J31: 45933 | K31: 45933 | L31: 45933 | M31: 45933 | N31: 45933 | O31: 45933 | P31: 45933 | Q31: 45933 | R31: 45933 | S31: 45933 | T31: 45933 | U31: 45933 | V31: 45933 | W31: 45933 | X31: 45933 | Y31: 45933
B32: Defect ID

Sheet submitFlashcard
A1: Code Module | C1: UserController | E1: Method | N1: Login
A2: Created By | C2: ChuVV | E2: Executed By | N2: ChuVV
A3: Test requirement
A4: Passed | C4: Failed | E4: Untested | J4: N/A/B | M4: Total Test Cases
A5: =COUNTIF(E40:HZ40,"P") -> 13 | C5: =COUNTIF(E40:HZ40,"F") -> 0 | E5: =SUM(M5,-A5,-C5) -> 0 | J5: =COUNTIF(A39:HV39,"N") -> 1 | K5: =COUNTIF(B39:HW39,"A") -> 10 | L5: =COUNTIF(C39:HX39,"B") -> 2 | M5: =COUNTA(A7:HN7) -> 13
E7: UTCID01 | F7: UTCID02 | G7: UTCID03 | H7: UTCID04 | I7: UTCID05 | J7: UTCID06 | K7: UTCID07 | L7: UTCID08 | M7: UTCID09 | N7: UTCID10 | O7: UTCID11 | P7: UTCID12 | Q7: UTCID13
A8: Condition | B8: Precondition
D9: Connected to the server | E9: O | F9: O | G9: O | H9: O | I9: O | J9: O | K9: O | L9: O
B10: studentId
C11: Valid student ID | D11: 1 | E11: O | F11: O | G11: O | H11: O | I11: O | J11: O
C12: non-exist student ID | D12: 9999 | K12: O
C13: null student Id | D13: null | L13: O
B14: vocabId
C15: Valid ID belonging to Chapter 2 | D15: 4 | E15: O | F15: O | H15: O | I15: O | J15: O | K15: O | L15: O
C16: null vocadId | D16: null | G16: O
B17: chapterId
C18: Valid Chapter ID | D18: 2 | E18: O | F18: O | G18: O | H18: O | I18: O | K18: O | L18: O
C19: null chapterID | D19: null
C20: "Valid Chapter ID, but Vocab 4 is not in Chapter 3." | D20: 3 | J20: O
B21: isMastered
C22: TRUE | D22: TRUE | E22: O | G22: O | H22: O | J22: O | K22: O | L22: O
C23: FALSE | D23: FALSE | F23: O
C24: null isMastered | D24: null | I24: O
A25: Confirm | B25: Return
D26: TRUE | E26: O | F26: O
D27: FALSE | G27: O | H27: O | I27: O | J27: O | K27: O | L27: O
B28: Exception
B31: Log message
D32: "Flashcard review submitted successfully" | E32: O | F32: O
D33: "Vocabulary ID must not be null" | G33: O
D34: "Chapter ID must not be null" | H34: O
D35: "Review result (isMastered) must not be null" | I35: O
D36: "Vocabulary does not belong to this chapter" | J36: O
D37: "Student not found" | K37: O
D38: "This exception is undedefined" | L38: O
A39: Result | B39: Type(N : Normal, A : Abnormal, B : Boundary) | E39: N | F39: A | G39: A | H39: A | I39: A | J39: A | K39: A | L39: A | M39: A | N39: A | O39: B | P39: A | Q39: B
B40: Passed/Failed | E40: P | F40: P | G40: P | H40: P | I40: P | J40: P | K40: P | L40: P | M40: P | N40: P | O40: P | P40: P | Q40: P
B41: Executed Date | E41: 45932 | F41: 45932 | G41: 45932 | H41: 45932 | I41: 45932 | J41: 45932 | K41: 45932 | L41: 45932 | M41: 45932 | N41: 45932 | O41: 45932 | P41: 45932 | Q41: 45932
B42: Defect ID

Sheet viewLearningProgress
A1: Code Module | C1: ProjectService | E1: Method | N1: Login
A2: Created By | C2: ChuVV | E2: Executed By | N2: ChuVV
A3: Test requirement
A4: Passed | C4: Failed | E4: Untested | J4: N/A/B | M4: Total Test Cases
A5: =COUNTIF(E27:IE27,"P") -> 14 | C5: =COUNTIF(E27:IE27,"F") -> 0 | E5: =SUM(M5,-A5,-C5) -> 0 | J5: =COUNTIF(A26:IA26,"N") -> 2 | K5: =COUNTIF(B26:IB26,"A") -> 10 | L5: =COUNTIF(C26:IC26,"B") -> 2 | M5: =COUNTA(A7:HS7) -> 14
E7: UTCID01 | F7: UTCID02 | G7: UTCID03 | H7: UTCID04 | I7: UTCID05 | J7: UTCID06 | K7: UTCID07 | L7: UTCID08 | M7: UTCID09 | N7: UTCID10 | O7: UTCID11 | P7: UTCID12 | Q7: UTCID13 | R7: UTCID14
A8: Condition | B8: Precondition
D9: Connected to the server | E9: O | F9: O | G9: O | H9: O | I9: O
B10: studentId
C11: Valid student ID | D11: 1 | E11: O | I11: O
C12: Valid student ID(with no progress history) | D12: 4 | F12: O
C13: non-exist studentID | D13: 999 | G13: O
C14: null studentID | D14: null | H14: O
C15: non-numeric studentID | D15: abc | I15: O
A16: Confirm | B16: Return
D17: TRUE | E17: O
D18: FALSE | F18: O | G18: O | H18: O | I18: O
B19: Exception
B22: Log message
D23: "Learning progress retrieved successfully" | E23: O
D24: "Learning progress retrieved successfully" (white page) | F24: O
D25: "This exception is undedefined" | G25: O | H25: O | I25: O
A26: Result | B26: Type(N : Normal, A : Abnormal, B : Boundary) | E26: N | F26: A | G26: A | H26: A | I26: A | J26: A | K26: B | L26: N | M26: A | N26: A | O26: A | P26: B | Q26: A | R26: A
B27: Passed/Failed | E27: P | F27: P | G27: P | H27: P | I27: P | J27: P | K27: P | L27: P | M27: P | N27: P | O27: P | P27: P | Q27: P | R27: P
B28: Executed Date | E28: 45948 | F28: 45948 | G28: 45948 | H28: 45948 | I28: 45948 | J28: 45948 | K28: 45948 | L28: 45948 | M28: 45948 | N28: 45948 | O28: 45948 | P28: 45948 | Q28: 45948 | R28: 45949
B29: Defect ID

Sheet viewWeekVocabulary
A1: Code Module | C1: ProjectService | E1: Method | N1: Login
A2: Created By | C2: ChuVV | E2: Executed By | N2: ChuVV
A3: Test requirement
A4: Passed | C4: Failed | E4: Untested | J4: N/A/B | M4: Total Test Cases
A5: =COUNTIF(E30:IE30,"P") -> 14 | C5: =COUNTIF(E30:IE30,"F") -> 0 | E5: =SUM(M5,-A5,-C5) -> 0 | J5: =COUNTIF(A29:IA29,"N") -> 2 | K5: =COUNTIF(B29:IB29,"A") -> 10 | L5: =COUNTIF(C29:IC29,"B") -> 2 | M5: =COUNTA(A7:HS7) -> 14
E7: UTCID01 | F7: UTCID02 | G7: UTCID03 | H7: UTCID04 | I7: UTCID05 | J7: UTCID06 | K7: UTCID07 | L7: UTCID08 | M7: UTCID09 | N7: UTCID10 | O7: UTCID11 | P7: UTCID12 | Q7: UTCID13 | R7: UTCID14
A8: Condition | B8: Precondition
D9: Connected to the server | E9: O | F9: O | G9: O | H9: O | I9: O | J9: O
B10: studentId
C11: Valid student ID | D11: 1 | E11: O | F11: O | G11: O
C12: non-exist studentID | D12: 999 | H12: O
C13: null studentID | D13: null | I13: O
C14: non-numeric studentID | D14: abc | J14: O
B15: limit
C16: null | D16: 1 | E16: O | H16: O | I16: O | J16: O
C17: numeric | D17: 4 | F17: O
C18: non-numeric | D18: abc | G18: O
A19: Confirm | B19: Return
D20: TRUE | E20: O | F20: O
D21: FALSE | G21: O | H21: O | I21: O | J21: O
B22: Exception
B25: Log message
D26: "Weak vocabulary retrieved successfully" | E26: O | F26: O
D27: "Student not found" | I27: O
D28: "This exception is undedefined" | G28: O | H28: O | J28: O
A29: Result | B29: Type(N : Normal, A : Abnormal, B : Boundary) | E29: N | F29: A | G29: A | H29: A | I29: A | J29: A | K29: B | L29: N | M29: A | N29: A | O29: A | P29: B | Q29: A | R29: A
B30: Passed/Failed | E30: P | F30: P | G30: P | H30: P | I30: P | J30: P | K30: P | L30: P | M30: P | N30: P | O30: P | P30: P | Q30: P | R30: P
B31: Executed Date | E31: 45948 | F31: 45948 | G31: 45948 | H31: 45948 | I31: 45948 | J31: 45948 | K31: 45948 | L31: 45948 | M31: 45948 | N31: 45948 | O31: 45948 | P31: 45948 | Q31: 45948 | R31: 45949
B32: Defect ID

Sheet getChapterList
A1: Code Module | C1: ProjectService | E1: Method | N1: Login
A2: Created By | C2: ChuVV | E2: Executed By | N2: ChuVV
A3: Test requirement
A4: Passed | C4: Failed | E4: Untested | J4: N/A/B | M4: Total Test Cases
A5: =COUNTIF(E26:IE26,"P") -> 4 | C5: =COUNTIF(E26:IE26,"F") -> 0 | E5: =SUM(M5,-A5,-C5) -> 0 | J5: =COUNTIF(A25:IA25,"N") -> 1 | K5: =COUNTIF(B25:IB25,"A") -> 3 | L5: =COUNTIF(C25:IC25,"B") -> 0 | M5: =COUNTA(A7:HS7) -> 4
E7: UTCID01 | F7: UTCID02 | G7: UTCID03 | H7: UTCID04
A8: Condition | B8: Precondition
D9: Connected to the server | E9: O | F9: O | G9: O | H9: O
B10: studentID
C11: null | D11: null | E11: O
C12: Valid student ID | D12: 1 | F12: O
C13: non-exist studentID | D13: 999 | G13: O
C14: non-numeric studentID | D14: abc | H14: O
A15: Confirm | B15: Return
D16: TRUE | E16: O
D17: FALSE | F17: O | G17: O | H17: O
B18: Exception
B21: Log message
D22: "System chapters retrieved successfully" | E22: O
D23: "My chapters retrieved successfully" | F23: O
D24: "This exception is undedefined" | G24: O | H24: O
A25: Result | B25: Type(N : Normal, A : Abnormal, B : Boundary) | E25: N | F25: A | G25: A | H25: A
B26: Passed/Failed | E26: P | F26: P | G26: P | H26: P
B27: Executed Date | E27: 45948 | F27: 45948 | G27: 45948 | H27: 45948
B28: Defect ID

Sheet createChapter
A1: Code Module | C1: UserController | E1: Method | N1: Login
A2: Created By | C2: ChuVV | E2: Executed By | N2: ChuVV
A3: Test requirement
A4: Passed | C4: Failed | E4: Untested | J4: N/A/B | M4: Total Test Cases
A5: =COUNTIF(E43:HZ43,"P") -> 13 | C5: =COUNTIF(E43:HZ43,"F") -> 0 | E5: =SUM(M5,-A5,-C5) -> 0 | J5: =COUNTIF(A42:HV42,"N") -> 1 | K5: =COUNTIF(B42:HW42,"A") -> 10 | L5: =COUNTIF(C42:HX42,"B") -> 2 | M5: =COUNTA(A7:HN7) -> 13
E7: UTCID01 | F7: UTCID02 | G7: UTCID03 | H7: UTCID04 | I7: UTCID05 | J7: UTCID06 | K7: UTCID07 | L7: UTCID08 | M7: UTCID09 | N7: UTCID10 | O7: UTCID11 | P7: UTCID12 | Q7: UTCID13
A8: Condition | B8: Precondition
D9: Connected to the server | E9: O | F9: O | G9: O | H9: O | I9: O | J9: O | K9: O | L9: O | M9: O
B10: studentId
C11: Valid student ID | D11: 1 | E11: O | F11: O | G11: O | H11: O | I11: O | J11: O
C12: invalid student id | D12: abc | K12: O
C13: non-exist student ID | D13: 9999 | L13: O
C14: null student Id | D14: null | M14: O
B15: chapterName
C16: Valid name | D16: Custom Chapter 1 | E16: O | H16: O | I16: O | J16: O | K16: O | L16: O | M16: O
C17: blank | F17: O
C18: >100 characters | D18: aaaa.....aaaaaa | G18: O
B19: level
C20: Valid level | D20: N5 | E20: O | F20: O | G20: O | I20: O | J20: O | K20: O | L20: O | M20: O
C21: null | D21: null | H21: O
B22: orderIndex
C23: Valid integer index | D23: 1 | E23: O | F23: O | G23: O | H23: O | K23: O | L23: O | M23: O
C24: null | D24: null | I24: O
C25: non-numeric | D25: abc | J25: O
B26: description
C27: valid description | D27: Practice vocabulary | E27: O | F27: O | G27: O | H27: O | I27: O | J27: O | K27: O | L27: O | M27: O
A28: Confirm | B28: Return
D29: TRUE | E29: O
D30: FALSE | F30: O | G30: O | H30: O | I30: O | J30: O | K30: O | L30: O | M30: O
B31: Exception
B34: Log message
D35: "Chapter created successfully" | E35: O
D36: "Chapter name must not be blank" | F36: O
D37: "Chapter name must not exceed 100 characters" | G37: O
D38: "Japanese level is required" | H38: O
D39: "Order index must not be null" | I39: O
D40: "Student not found" | L40: O
D41: "This exception is undedefined" | J41: O | K41: O | M41: O
A42: Result | B42: Type(N : Normal, A : Abnormal, B : Boundary) | E42: N | F42: A | G42: A | H42: A | I42: A | J42: A | K42: A | L42: A | M42: A | N42: A | O42: B | P42: A | Q42: B
B43: Passed/Failed | E43: P | F43: P | G43: P | H43: P | I43: P | J43: P | K43: P | L43: P | M43: P | N43: P | O43: P | P43: P | Q43: P
...

Sheet getDetailChapter
A1: Code Module | C1: ProjectService | E1: Method | N1: Login
A2: Created By | C2: ChuVV | E2: Executed By | N2: ChuVV
A3: Test requirement
A4: Passed | C4: Failed | E4: Untested | J4: N/A/B | M4: Total Test Cases
A5: =COUNTIF(E33:IE33,"P") -> 13 | C5: =COUNTIF(E33:IE33,"F") -> 0 | E5: =SUM(M5,-A5,-C5) -> 0 | J5: =COUNTIF(A32:IA32,"N") -> 2 | K5: =COUNTIF(B32:IB32,"A") -> 9 | L5: =COUNTIF(C32:IC32,"B") -> 2 | M5: =COUNTA(A7:HS7) -> 13
E7: UTCID01 | F7: UTCID02 | G7: UTCID03 | H7: UTCID04 | I7: UTCID05 | J7: UTCID06 | K7: UTCID07 | L7: UTCID08 | M7: UTCID09 | N7: UTCID10 | O7: UTCID11 | P7: UTCID12 | Q7: UTCID13
A8: Condition | B8: Precondition
D9: Connected to the server | E9: O | F9: O | G9: O | H9: O | I9: O | J9: O | K9: O
B10: studentId
C11: Valid student ID | D11: 1 | E11: O | F11: O | G11: O | H11: O
C12: Different valid student ID | D12: 2 | I12: O
C13: non-exist studentID | D13: 999 | J13: O
C14: null studentID | D14: null | K14: O | L14: O
C15: non-numeric studentID | D15: abc
B16: chapterId
C17: Valid system chapter ID | D17: 1 | E17: O | J17: O | K17: O | L17: O
C18: Valid custom chapter ID belonging to Student 1 | D18: 4 | F18: O | I18: O
C19: Non-existent chapter ID | D19: 999 | G19: O
C20: Non-numeric chapter ID | D20: abc | H20: O
A21: Confirm | B21: Return
D22: TRUE | E22: O | F22: O | J22: O
D23: FALSE | G23: O | H23: O | I23: O | K23: O | L23: O
B24: Exception
B27: Log message
D28: "Chapter retrieved successfully" | E28: O | F28: O | J28: O
D29: "Vocabulary chapter not found" | G29: O
D30: "You do not have permission to access this chapter" | I30: O
D31: "This exception is undedefined" | H31: O | K31: O | L31: O
A32: Result | B32: Type(N : Normal, A : Abnormal, B : Boundary) | E32: N | F32: A | G32: A | H32: A | I32: A | J32: A | K32: B | L32: N | M32: A | N32: A | O32: A | P32: B | Q32: A
B33: Passed/Failed | E33: P | F33: P | G33: P | H33: P | I33: P | J33: P | K33: P | L33: P | M33: P | N33: P | O33: P | P33: P | Q33: P
B34: Executed Date | E34: 45948 | F34: 45948 | G34: 45948 | H34: 45948 | I34: 45948 | J34: 45948 | K34: 45948 | L34: 45948 | M34: 45948 | N34: 45948 | O34: 45948 | P34: 45948 | Q34: 45948
B35: Defect ID

Sheet updateChapterDetail
A1: Code Module | C1: UserController | E1: Method | N1: Login
A2: Created By | C2: ChuVV | E2: Executed By | N2: ChuVV
A3: Test requirement
A4: Passed | C4: Failed | E4: Untested | J4: N/A/B | M4: Total Test Cases
A5: =COUNTIF(E43:IE43,"P") -> 5 | C5: =COUNTIF(E43:IE43,"F") -> 0 | E5: =SUM(M5,-A5,-C5) -> 0 | J5: =COUNTIF(A42:IA42,"N") -> 1 | K5: =COUNTIF(B42:IB42,"A") -> 4 | L5: =COUNTIF(C42:IC42,"B") -> 0 | M5: =COUNTA(A7:HS7) -> 5
E7: UTCID01 | F7: UTCID02 | G7: UTCID03 | H7: UTCID04 | I7: UTCID05
A8: Condition | B8: Precondition
D9: Connected to the server | E9: O | F9: O | G9: O | H9: O | I9: O
B10: studentID
C11: Valid student ID | D11: 12 | E11: O | I11: O
C12: invalid student id | D12: 999 | F12: O
C13: non-exist student ID | D13: null | G13: O
C14: null student Id | D14: abc | H14: O
B15: chaptername
C16: Valid name | D16: Update name | E16: O | F16: O | G16: O | H16: O
C17: blank
C18: >100 characters | D18: aaaa......aaaaa | I18: O
B19: level
C20: Valid level | D20: N5 | E20: O | I20: O
C21: null | D21: null | F21: O
B22: order index
C23: Valid integer index | D23: 1 | E23: O | F23: O | G23: O | H23: O
C24: null | D24: null
C25: non-numeric | D25: abc | I25: O
B26: description
C27: valid description | D27: Practice vocabulary | E27: O | F27: O | G27: O | H27: O
A30: Confirm | B30: Return
D31: TRUE | E31: O
D32: FALSE | F32: O | G32: O | H32: O | I32: O
B33: Exception
B36: Log message
D37: "Project deleted successfully" | E37: O
D38: "Project ID is required" | G38: O
D39: "Project not found" | F39: O
D40: "Invalid project ID format" | H40: O
D41: "Published project cannot be deleted" | I41: O
A42: Result | B42: Type(N : Normal, A : Abnormal, B : Boundary) | E42: N | F42: A | G42: A | H42: A | I42: A
B43: Passed/Failed | E43: P | F43: P | G43: P | H43: P | I43: P
B44: Executed Date | E44: 45948 | F44: 45948 | G44: 45948 | H44: 45948 | I44: 45948
B45: Defect ID
